Workbook

Sheet Data 1
A1: Start Time : 2023-11-15 15:05:12
A2: Frame | B2: Time | C2: Battery voltage | D2: Ignition switch condition | E2: First EGR closed position (AD Conversion) | F2: Fuel Temp Sensor (physical Value) | G2: Turbine inlet temperature (physical value) | H2: EGR valve duty cycle | I2: Brake switch condition | J2: State variable showing the condition of the engine | K2: Coolant temp (physical value) | L2: Engine speed | M2: Number of MDP update failed | N2: Number of MDP update succeed | O2: Total soot mas inside the DPF calulated based on model | P2: Transmission oil temp switch condition | Q2: Oil pressure | R2: Pedal position | S2: Atmospheric pressure | T2: Pedal position from potentiometer track 1 | U2: Pedal position from potentiometer track 2 | V2: Hand pedal position from potentiometer track 1 | W2: Hand pedal position from potentiometer track 2 | X2: Fuel filter feedback (AD conversion) | Y2: Turbine inlet preesure (estimate) | Z2: SCR outlet temperature | AA2: EGR rate position (demand value) | AB2: Throttle valve duty cycle | AC2: After fuel quantity (demand) | AD2: Total fuel injection quantity | AE2: Main fuel injection quantity | AF2: Pilot 1 fuel inection quantity | AG2: Pilot 2 fuel inection quantity | AH2: Post 1 fuel inection quantity | AI2: Post 2 fuel inection quantity | AJ2: Injection balancing delta speed of Cyliner 1 | AK2: Injection balancing delta speed of Cyliner 3 (D18 = Injector 2) | AL2: Injection balancing delta speed of Cyliner 4 (D18 = Injector 3) | AM2: Injection balancing delta speed of Cyliner 2 | AN2: After injection condition | AO2: Main injection timing | AP2: Pilot1 injection timing demand | AQ2: Pilot2 injection timing demand | AR2: Post1 injection timing demand | AS2: Post2 injection timing demand | AT2: Rail pressure (demand value) | AU2: Rail pressure gap (demand vs actual feedback) | AV2: Actual fast indicated mean effective pressure | AW2: Actual slow indicated mean effective pressure | AX2: Desired fast indicated mean effective pressure | AY2: Desired slow indicated mean effective pressure | AZ2: Idle speed target | BA2: Maximum indicated torque | BB2: Brake Lamp Switch condition | BC2: Oil pressure warning lamp condition | BD2: Inching pedal switch condition | BE2: Multi torque switch condition | BF2: Parking Brake switch condition | BG2: PTO switch condition | BH2: Water in fuel filter condition | BI2: Emergency Switch condition | BJ2: Total engine running time | BK2: Total fuel used by the engine | BL2: Total vehicle run time | BM2: IMV current demand | BN2: Cluth switch condition | BO2: EGR valve position | BP2: Air mass flow (1 injection cycle) | BQ2: EGR valve position (AD Conversion) | BR2: Manifold air pressure (raw) | BS2: Rail pressure (raw) | BT2: Intake manifold temperature | BU2: Throttle feedback position from AD Conversion | BV2: Regeneration state | BW2: Glow plugs condition | BX2: Ambient temperature | BY2: Throttle position (desired) | BZ2: Actual engine brake torque | CA2: Actual indicated torque | CB2: Intake port air mass flow | CC2: Intake port air mass flow (speed) | CD2: Oil pressure | CE2: Output temperature from cnts linearization map | CF2: SCR inlet temperature | CG2: DOC in temperature | CH2: Target DOC out temperature (DeSox Mode) | CI2: Regen switch is the inhibited state | CJ2: Air/Fuel ratio | CK2: Intake air estimation | CL2: EGR valve duty rate (desired) | CM2: EGR rate (Intake port) | CN2: DeSOx state | CO2: Check engine lamp condition | CP2: Glow plug warning lamp signal condition | CQ2: MIL Lamp condition | CR2: Supply Module external ambient temperature | CS2: Fuel filter pressure | CT2: Cam sensor APS value | CU2: Cam sensor condition | CV2: Crank Sensor APS value | CW2: Crank sensor condition | CX2: Cam & Crank sensor communicating | CY2: IMV current feedback | CZ2: Max torque value | DA2: Reduce torque value | DB2: Smoke Limit Active condition | DC2: Atmospheric pressure | DD2: Coolant temp (AD Conversion) | DE2: Turbine inlet temperature (AD Conversion) | DF2: Manifold air pressure sensor (AD Conversion) | DG2: Air mass flow (Feedback) | DH2: Fuel tank level | DI2: Intake air temperature (Feedback) | DJ2: Actual Throttle feedback position from AD Conversion | DK2: Engine running time (1 driving cycle) | DL2: Requested Engine Speed | DM2: Filtered EGR flow correction fraction during fail diagnosis conditions | DN2: EGR flow diagnosis enabled | DO2: Non-corrected intake port fresh air flow | DP2: Value of period signal (HFM AMF)
C3: P_L_Battery_raw | D3: P_L_Ignition_switch | E3: P_L_Egr_close_pos_mean_nvv | F3: P_L_Fuel_temp_raw | G3: P_L_Turb_in_temp_raw | H3: ACM_EGR_VALVE_DRIVE_DUTY_CYCLE | I3: IN_Brake_switch | J3: SMC_ENGINE_STATE | K3: P_L_Coolant_temperature | L3: IN_Engine_cycle_speed | M3: I_C_Mdp_nb_update_failure_nvv | N3: I_C_Mdp_nb_update_success_nvv | O3: P_T_Dpf_model_soot_mass_nvv | P3: ICV_Oil_trans_temp_switch | Q3: IN_Oil_pressure | R3: IN_Pedal_position | S3: P_L_Atmosp_raw | T3: P_L_Pedal_foot_t1_raw | U3: P_L_Pedal_foot_t2_raw | V3: P_L_Pedal_hand_t1_raw | W3: P_L_Pedal_hand_t2_raw | X3: P_L_Wif_feedback_cnts | Y3: PSE_Turbine_in_press_est | Z3: TSE_Dpf_out_temp | AA3: ACM_Egr_position_dmnd | AB3: ACM_Throt_duty_cycle | AC3: FQD_Chkd_after_fuel_dmnd | AD3: FQD_Chkd_inj_fuel_dmnd | AE3: FQD_Chkd_main_fuel_dmnd | AF3: FQD_Chkd_pilot1_fuel_dmnd | AG3: FQD_Chkd_pilot2_fuel_dmnd | AH3: FQD_Chkd_post1_fuel_dmnd | AI3: FQD_Chkd_post2_fuel_dmnd | AJ3: IN_Bal_delta_speed[0] | AK3: IN_Bal_delta_speed[1] | AL3: IN_Bal_delta_speed[2] | AM3: IN_Bal_delta_speed[3] | AN3: ITD_Chkd_after_hyd_us_sep | AO3: ITD_Chkd_main_hyd_timing | AP3: ITD_Chkd_pilot1_hyd_timing | AQ3: ITD_Chkd_pilot2_hyd_timing | AR3: ITD_Chkd_post1_hyd_timing | AS3: ITD_Chkd_post2_hyd_timing | AT3: RPC_Rail_pressure_dmnd | AU3: RPC_Rail_pressure_error | AV3: T_D_Actual_fast_imep | AW3: T_D_Actual_slow_imep | AX3: T_D_Dsrd_fast_imep | AY3: T_D_Dsrd_slow_imep | AZ3: T_D_Idle_target | BA3: T_D_Max_indicated_torque | BB3: ICI_Brake_lamp_output | BC3: ICI_Oil_pressure_lamp_output | BD3: IN_Engine_speed_limit_active | BE3: IN_Multiple_torque_state | BF3: IN_Park_brake_switch | BG3: IN_Pto_switch | BH3: IN_Water_in_fuel_state | BI3: P_L_Emergency_switch_active | BJ3: EUD_Engine_run_time_total_nvv | BK3: EUD_Engine_total_fuel_nvv | BL3: EUD_Vehicle_run_time_total_nvv | BM3: RPC_Im_crt_dmnd | BN3: IN_Clutch_switch | BO3: IN_Egr_position | BP3: IN_Inlet_air_flow | BQ3: P_L_Egr_feedback_pos_cnts | BR3: P_L_MAP_RAW | BS3: P_L_RAIL_PRES_RAW | BT3: P_L_T2_temp_raw | BU3: P_L_Thrtl_feedback_abs_pos | BV3: P_T_REGEN_STATE | BW3: SAC_Glow_plug_output | BX3: TSE_Ambient_air_temp | BY3: ACM_Throt_desired_pos | BZ3: T_D_Actual_brake_torque | CA3: T_D_Actual_indicated_torque | CB3: ACM_INTAKE_PORT_AIR_FLOW_MAF | CC3: ACM_INTAKE_PORT_AIR_FLOW_SPD | CD3: P_L_OIL_PRESSURE | CE3: P_L_OIL_TEMPERATURE | CF3: TSE_Dpf_in_temp | CG3: TSE_Doc_in_temp | CH3: FQD_DPF_REGEN_TARGET_TEMP | CI3: P_L_DPF_REGEN_INHIBITED | CJ3: AFC_Air_fuel_ratio | CK3: ACM_Air_estimation_raw_error | CL3: ACM_EGR_RATE_DESIRED | CM3: ACM_EGR_RATE | CN3: P_L_Dpf_regen_forced | CO3: ICI_CE_LAMP_OUTPUT | CP3: ICI_Glow_plug_lamp_output | CQ3: ICI_Mi_lamp_output | CR3: IN_Ext_air_temp | CS3: IN_Fuel_filter_pressure | CT3: P_L_Aps_cam_period | CU3: P_L_aps_cam_valid | CV3: P_L_Aps_crank_period | CW3: P_L_aps_crank_valid | CX3: P_L_aps_sync_tasks_enabled | CY3: P_L_Im_crt_fb | CZ3: T_D_Max_brake_torque | DA3: T_D_Reduced_torque | DB3: T_D_Smoke_limit_active | DC3: IN_Atmospheric_pressure | DD3: P_L_Coolant_temp_cnts | DE3: P_L_Turb_in_temp_cnts | DF3: P_L_Map_cnts | DG3: IN_Amf_feedback | DH3: IN_Fuel_tank_level | DI3: P_L_Inlet_air_temp_raw | DJ3: P_L_Thrtl_feedback_pos_cnts | DK3: SMC_Engine_running_time_cpy | DL3: T_D_Vdg_tsc1_req_speed | DM3: ACM_Egr_flow_corr_fract_filt | DN3: ACM_Egr_flow_diag_ena | DO3: ACM_Intake_port_air_flow_raw_spd | DP3: P_L_Amf_period
C4: V | E4: ADcnt | F4: deg F | G4: deg F | H4: % | K4: deg F | L4: rpm | M4: - | N4: - | O4: g | P4: FALSE/TRUE | Q4: psi | R4: % | S4: psi | T4: % | U4: % | V4: % | W4: % | X4: ADcnt | Y4: psi | Z4: deg F | AA4: % | AB4: % | AC4: mg/stroke | AD4: mg/stroke | AE4: mg/stroke | AF4: mg/stroke | AG4: mg/stroke | AH4: mg/stroke | AI4: mg/stroke | AJ4: rpm | AK4: rpm | AL4: rpm | AM4: rpm | AN4: us | AO4: edeg | AP4: edeg | AQ4: edeg | AR4: edeg | AS4: edeg | AT4: psi | AU4: psi | AV4: psi | AW4: psi | AX4: psi | AY4: psi | AZ4: rpm | BA4: Nm | BB4: FALSE/TRUE | BC4: FALSE/TRUE | BD4: T/F | BF4: FALSE/TRUE | BG4: FALSE/TRUE | BH4: FALSE/TRUE | BI4: T/F | BJ4: s | BK4: L | BL4: s | BM4: mA | BO4: % | BP4: g/s | BQ4: - | BR4: psi | BS4: psi | BT4: deg F | BU4: % | BW4: FALSE/TRUE | BX4: deg F | BY4: % | BZ4: Nm | CA4: Nm | CB4: g/s | CC4: g/s | CD4: kPa | CE4: deg F | CF4: deg F | CG4: deg F | CH4: deg F | CK4: g/s | CL4: g/s | CM4: g/s | CO4: T/F | CP4: FALSE/TRUE | CQ4: FALSE/TRUE | CR4: degC | CS4: kPa | CT4: us | CU4: T/F | CV4: us | CW4: T/F | CX4: T/F | CY4: mA | CZ4: Nm | DA4: Nm | DB4: T/F | DC4: psi | DD4: - | DE4: ADcnt | DF4: ADcnt | DG4: mg/stroke | DH4: % | DI4: deg F | DJ4: - | DK4: s | DL4: rpm | DM4: - | DN4: - | DO4: g/s | DP4: us
A5: -18 | B5: -1.8 | C5: 12.3 | D5: 1 | E5: 794 | F5: 109.4 | G5: 1688 | H5: -10 | I5: 0 | J5: 2 | K5: 127.4 | L5: 1201 | M5: 1051 | N5: 2544 | O5: 0 | P5: 0 | Q5: 20.9 | R5: 0 | S5: 14.2 | T5: 0 | U5: 0 | V5: 0 | W5: 0 | X5: 704 | Y5: 16.5 | Z5: 32 | AA5: 0 | AB5: 0 | AC5: 0 | AD5: 10 | AE5: 6 | AF5: 3 | AG5: 0 | AH5: 0 | AI5: 0 | AJ5: -8 | AK5: -16 | AL5: -8 | AM5: -8 | AN5: 0 | AO5: 2 | AP5: 16 | AQ5: -1 | AR5: -255 | AS5: -255 | AT5: 9717.7 | AU5: 145 | AV5: 47.9 | AW5: 95.7 | AX5: 47.9 | AY5: 94.3 | AZ5: 1120 | BA5: 144 | BB5: 0 | BC5: 0 | BD5: 0 | BE5: 0 | BF5: 1 | BG5: 0 | BH5: 0 | BI5: 0 | BJ5: 7389991 | BK5: 11998.05 | BL5: 7549921 | BM5: 800 | BN5: 0 | BO5: -0.236 | BP5: 18 | BQ5: 792 | BR5: 13.6 | BS5: 3916.1 | BT5: 104 | BU5: 0 | BV5: 0 | BW5: 1 | BX5: 32 | BY5: 99 | BZ5: 92.69 | CA5: 120.38 | CB5: 20.84 | CC5: 21.41 | CD5: 511.94 | CE5: 127 | CF5: 32 | CG5: 326.3 | CH5: 32 | CI5: 0 | CJ5: 38.18 | CK5: -0.06 | CL5: 0 | CM5: 0 | CN5: 0 | CO5: 0 | CP5: 0 | CQ5: 0 | CR5: Not Supported | CS5: Not Supported | CT5: 9780 | CU5: 1 | CV5: 978 | CW5: 1 | CX5: 1 | CY5: 806.81 | CZ5: 179 | DA5: 2016 | DB5: 0 | DC5: 14.4 | DD5: 204 | DE5: 4095 | DF5: 212 | DG5: 563 | DH5: 0 | DI5: 86 | DJ5: 0 | DK5: 1 | DL5: 0 | DM5: 1 | DN5: FALSE | DO5: 22.625 | DP5: 551
A6: -17 | B6: -1.7 | C6: 12.3 | D6: 1 | E6: 794 | F6: 109.4 | G6: 1688 | H6: -10 | I6: 0 | J6: 2 | K6: 127.4 | L6: 1201 | M6: 1051 | N6: 2544 | O6: 0 | P6: 0 | Q6: 20.9 | R6: 0 | S6: 14.2 | T6: 0 | U6: 0 | V6: 0 | W6: 0 | X6: 704 | Y6: 16.5 | Z6: 32 | AA6: 0 | AB6: 0 | AC6: 0 | AD6: 10 | AE6: 6 | AF6: 3 | AG6: 0 | AH6: 0 | AI6: 0 | AJ6: -8 | AK6: -16 | AL6: -8 | AM6: -8 | AN6: 0 | AO6: 2 | AP6: 16 | AQ6: -1 | AR6: -255 | AS6: -255 | AT6: 9717.7 | AU6: 145 | AV6: 47.9 | AW6: 95.7 | AX6: 47.9 | AY6: 94.3 | AZ6: 1120 | BA6: 144 | BB6: 0 | BC6: 0 | BD6: 0 | BE6: 0 | BF6: 1 | BG6: 0 | BH6: 0 | BI6: 0 | BJ6: 7389992 | BK6: 11998.05 | BL6: 7549922 | BM6: 800 | BN6: 0 | BO6: -0.236 | BP6: 18 | BQ6: 792 | BR6: 13.6 | BS6: 3916.1 | BT6: 104 | BU6: 0 | BV6: 0 | BW6: 1 | BX6: 32 | BY6: 99 | BZ6: 92.69 | CA6: 120.38 | CB6: 20.84 | CC6: 21.41 | CD6: 511.94 | CE6: 127 | CF6: 32 | CG6: 326.3 | CH6: 32 | CI6: 0 | CJ6: 38.18 | CK6: -0.06 | CL6: 0 | CM6: 0 | CN6: 0 | CO6: 0 | CP6: 0 | CQ6: 0 | CR6: Not Supported | CS6: Not Supported | CT6: 9780 | CU6: 1 | CV6: 978 | CW6: 1 | CX6: 1 | CY6: 806.81 | CZ6: 179 | DA6: 2016 | DB6: 0 | DC6: 14.4 | DD6: 204 | DE6: 4095 | DF6: 212 | DG6: 563 | DH6: 0 | DI6: 86 | DJ6: 0 | DK6: 1 | DL6: 0 | DM6: 1 | DN6: FALSE | DO6: 22.625 | DP6: 551
A7: -16 | B7: -1.6 | C7: 12.3 | D7: 1 | E7: 794 | F7: 109.4 | G7: 1688 | H7: -10 | I7: 0 | J7: 2 | K7: 127.4 | L7: 1201 | M7: 1051 | N7: 2544 | O7: 0 | P7: 0 | Q7: 20.9 | R7: 0 | S7: 14.2 | T7: 0 | U7: 0 | V7: 0 | W7: 0 | X7: 704 | Y7: 16.5 | Z7: 32 | AA7: 0 | AB7: 0 | AC7: 0 | AD7: 10 | AE7: 6 | AF7: 3 | AG7: 0 | AH7: 0 | AI7: 0 | AJ7: -8 | AK7: -16 | AL7: -8 | AM7: -8 | AN7: 0 | AO7: 2 | AP7: 16 | AQ7: -1 | AR7: -255 | AS7: -255 | AT7: 9717.7 | AU7: 145 | AV7: 47.9 | AW7: 95.7 | AX7: 47.9 | AY7: 94.3 | AZ7: 1120 | BA7: 144 | BB7: 0 | BC7: 0 | BD7: 0 | BE7: 0 | BF7: 1 | BG7: 0 | BH7: 0 | BI7: 0 | BJ7: 7389992 | BK7: 11998.05 | BL7: 7549922 | BM7: 810 | BN7: 0 | BO7: -0.236 | BP7: 22 | BQ7: 796 | BR7: 14.5 | BS7: 10587.9 | BT7: 104 | BU7: 0 | BV7: 0 | BW7: 1 | BX7: 32 | BY7: 99 | BZ7: 92.69 | CA7: 120.38 | CB7: 20.84 | CC7: 21.41 | CD7: 511.94 | CE7: 127 | CF7: 32 | CG7: 326.3 | CH7: 32 | CI7: 0 | CJ7: 38.18 | CK7: -0.06 | CL7: 0 | CM7: 0 | CN7: 0 | CO7: 0 | CP7: 0 | CQ7: 0 | CR7: Not Supported | CS7: Not Supported | CT7: 9780 | CU7: 1 | CV7: 978 | CW7: 1 | CX7: 1 | CY7: 806.81 | CZ7: 179 | DA7: 2016 | DB7: 0 | DC7: 14.4 | DD7: 204 | DE7: 4095 | DF7: 212 | DG7: 563 | DH7: 0 | DI7: 86 | DJ7: 0 | DK7: 1 | DL7: 0 | DM7: 1 | DN7: FALSE | DO7: 22.625 | DP7: 551
A8: -15 | B8: -1.5 | C8: 12.3 | D8: 1 | E8: 794 | F8: 109.4 | G8: 1688 | H8: -10 | I8: 0 | J8: 2 | K8: 127.4 | L8: 1201 | M8: 1051 | N8: 2544 | O8: 0 | P8: 0 | Q8: 20.9 | R8: 0 | S8: 14.2 | T8: 0 | U8: 0 | V8: 0 | W8: 0 | X8: 704 | Y8: 16.5 | Z8: 32 | AA8: 0 | AB8: 0 | AC8: 0 | AD8: 10 | AE8: 6 | AF8: 3 | AG8: 0 | AH8: 0 | AI8: 0 | AJ8: -8 | AK8: -16 | AL8: -8 | AM8: -8 | AN8: 0 | AO8: 2 | AP8: 16 | AQ8: -1 | AR8: -255 | AS8: -255 | AT8: 9717.7 | AU8: 145 | AV8: 47.9 | AW8: 95.7 | AX8: 47.9 | AY8: 94.3 | AZ8: 1120 | BA8: 144 | BB8: 0 | BC8: 0 | BD8: 0 | BE8: 0 | BF8: 1 | BG8: 0 | BH8: 0 | BI8: 0 | BJ8: 7389992 | BK8: 11998.05 | BL8: 7549922 | BM8: 810 | BN8: 0 | BO8: -0.236 | BP8: 22 | BQ8: 796 | BR8: 14.5 | BS8: 10587.9 | BT8: 104 | BU8: 0 | BV8: 0 | BW8: 1 | BX8: 33.8 | BY8: 99 | BZ8: 44.5 | CA8: 72.44 | CB8: 20.84 | CC8: 21.41 | CD8: 511.94 | CE8: 127 | CF8: 32 | CG8: 326.3 | CH8: 32 | CI8: 0 | CJ8: 38.18 | CK8: -0.06 | CL8: 0 | CM8: 0 | CN8: 0 | CO8: 0 | CP8: 0 | CQ8: 0 | CR8: Not Supported | CS8: Not Supported | CT8: 9780 | CU8: 1 | CV8: 978 | CW8: 1 | CX8: 1 | CY8: 806.81 | CZ8: 179 | DA8: 2016 | DB8: 0 | DC8: 14.4 | DD8: 204 | DE8: 4095 | DF8: 212 | DG8: 563 | DH8: 0 | DI8: 86 | DJ8: 0 | DK8: 1 | DL8: 0 | DM8: 1 | DN8: FALSE | DO8: 22.625 | DP8: 551
A9: -14 | B9: -1.4 | C9: 12.3 | D9: 1 | E9: 794 | F9: 109.4 | G9: 1688 | H9: -10 | I9: 0 | J9: 2 | K9: 127.4 | L9: 1201 | M9: 1051 | N9: 2544 | O9: 0 | P9: 0 | Q9: 20.9 | R9: 0 | S9: 14.2 | T9: 0 | U9: 0 | V9: 0 | W9: 0 | X9: 704 | Y9: 16.5 | Z9: 32 | AA9: 0 | AB9: 0 | AC9: 0 | AD9: 10 | AE9: 6 | AF9: 3 | AG9: 0 | AH9: 0 | AI9: 0 | AJ9: -8 | AK9: -16 | AL9: -8 | AM9: -8 | AN9: 0 | AO9: 2 | AP9: 16 | AQ9: -1 | AR9: -255 | AS9: -255 | AT9: 9717.7 | AU9: 145 | AV9: 47.9 | AW9: 95.7 | AX9: 47.9 | AY9: 94.3 | AZ9: 1120 | BA9: 144 | BB9: 0 | BC9: 0 | BD9: 0 | BE9: 0 | BF9: 1 | BG9: 0 | BH9: 0 | BI9: 0 | BJ9: 7389992 | BK9: 11998.05 | BL9: 7549922 | BM9: 810 | BN9: 0 | BO9: -0.236 | BP9: 22 | BQ9: 796 | BR9: 14.5 | BS9: 10587.9 | BT9: 104 | BU9: 0 | BV9: 0 | BW9: 1 | BX9: 33.8 | BY9: 99 | BZ9: 44.5 | CA9: 72.44 | CB9: 22.53 | CC9: 22.47 | CD9: 538.63 | CE9: 127 | CF9: 32 | CG9: 295.3 | CH9: 32 | CI9: 0 | CJ9: 38.18 | CK9: -0.06 | CL9: 0 | CM9: 0 | CN9: 0 | CO9: 0 | CP9: 0 | CQ9: 0 | CR9: Not Supported | CS9: Not Supported | CT9: 9780 | CU9: 1 | CV9: 978 | CW9: 1 | CX9: 1 | CY9: 806.81 | CZ9: 179 | DA9: 2016 | DB9: 0 | DC9: 14.4 | DD9: 204 | DE9: 4095 | DF9: 212 | DG9: 563 | DH9: 0 | DI9: 86 | DJ9: 0 | DK9: 1 | DL9: 0 | DM9: 1 | DN9: FALSE | DO9: 22.625 | DP9: 551
A10: -13 | B10: -1.3 | C10: 12.3 | D10: 1 | E10: 794 | F10: 109.4 | G10: 1688 | H10: -10 | I10: 0 | J10: 2 | K10: 127.4 | L10: 1201 | M10: 1051 | N10: 2544 | O10: 0 | P10: 0 | Q10: 20.9 | R10: 0 | S10: 14.2 | T10: 0 | U10: 0 | V10: 0 | W10: 0 | X10: 704 | Y10: 16.5 | Z10: 32 | AA10: 0 | AB10: 0 | AC10: 0 | AD10: 10 | AE10: 6 | AF10: 3 | AG10: 0 | AH10: 0 | AI10: 0 | AJ10: -8 | AK10: -16 | AL10: -8 | AM10: -8 | AN10: 0 | AO10: 2 | AP10: 16 | AQ10: -1 | AR10: -255 | AS10: -255 | AT10: 9717.7 | AU10: 145 | AV10: 47.9 | AW10: 95.7 | AX10: 47.9 | AY10: 94.3 | AZ10: 1120 | BA10: 144 | BB10: 0 | BC10: 0 | BD10: 0 | BE10: 0 | BF10: 1 | BG10: 0 | BH10: 0 | BI10: 0 | BJ10: 7389992 | BK10: 11998.05 | BL10: 7549922 | BM10: 810 | BN10: 0 | BO10: -0.236 | BP10: 22 | BQ10: 796 | BR10: 14.5 | BS10: 10587.9 | BT10: 104 | BU10: 0 | BV10: 0 | BW10: 1 | BX10: 33.8 | BY10: 99 | BZ10: 44.5 | CA10: 72.44 | CB10: 22.53 | CC10: 22.47 | CD10: 538.63 | CE10: 127 | CF10: 32 | CG10: 295.3 | CH10: 32 | CI10: 0 | CJ10: 50.89 | CK10: 0.41 | CL10: 0 | CM10: 0 | CN10: 0 | CO10: 0 | CP10: 0 | CQ10: 0 | CR10: Not Supported | CS10: Not Supported | CT10: 9780 | CU10: 1 | CV10: 978 | CW10: 1 | CX10: 1 | CY10: 806.81 | CZ10: 179 | DA10: 2016 | DB10: 0 | DC10: 14.4 | DD10: 204 | DE10: 4095 | DF10: 212 | DG10: 563 | DH10: 0 | DI10: 86 | DJ10: 0 | DK10: 1 | DL10: 0 | DM10: 1 | DN10: FALSE | DO10: 22.625 | DP10: 551
A11: -12 | B11: -1.2 | C11: 12.3 | D11: 1 | E11: 794 | F11: 109.4 | G11: 1688 | H11: -10 | I11: 0 | J11: 2 | K11: 127.4 | L11: 1201 | M11: 1051 | N11: 2544 | O11: 0 | P11: 0 | Q11: 20.9 | R11: 0 | S11: 14.2 | T11: 0 | U11: 0 | V11: 0 | W11: 0 | X11: 704 | Y11: 16.5 | Z11: 32 | AA11: 0 | AB11: 0 | AC11: 0 | AD11: 10 | AE11: 6 | AF11: 3 | AG11: 0 | AH11: 0 | AI11: 0 | AJ11: -8 | AK11: -16 | AL11: -8 | AM11: -8 | AN11: 0 | AO11: 2 | AP11: 16 | AQ11: -1 | AR11: -255 | AS11: -255 | AT11: 9717.7 | AU11: 145 | AV11: 47.9 | AW11: 95.7 | AX11: 47.9 | AY11: 94.3 | AZ11: 1120 | BA11: 144 | BB11: 0 | BC11: 0 | BD11: 0 | BE11: 0 | BF11: 1 | BG11: 0 | BH11: 0 | BI11: 0 | BJ11: 7389992 | BK11: 11998.05 | BL11: 7549922 | BM11: 810 | BN11: 0 | BO11: -0.236 | BP11: 22 | BQ11: 796 | BR11: 14.5 | BS11: 10587.9 | BT11: 104 | BU11: 0 | BV11: 0 | BW11: 1 | BX11: 33.8 | BY11: 99 | BZ11: 44.5 | CA11: 72.44 | CB11: 22.53 | CC11: 22.47 | CD11: 538.63 | CE11: 127 | CF11: 32 | CG11: 295.3 | CH11: 32 | CI11: 0 | CJ11: 50.89 | CK11: 0.41 | CL11: 0 | CM11: 0 | CN11: 0 | CO11: 0 | CP11: 0 | CQ11: 0 | CR11: Not Supported | CS11: Not Supported | CT11: 16515 | CU11: 1 | CV11: 865 | CW11: 1 | CX11: 1 | CY11: 821.44 | CZ11: 179 | DA11: 2016 | DB11: 0 | DC11: 14.4 | DD11: 204 | DE11: 4095 | DF11: 212 | DG11: 563 | DH11: 0 | DI11: 86 | DJ11: 0 | DK11: 1 | DL11: 0 | DM11: 1 | DN11: FALSE | DO11: 22.625 | DP11: 551
A12: -11 | B12: -1.1 | C12: 12.3 | D12: 1 | E12: 794 | F12: 109.4 | G12: 1688 | H12: -10 | I12: 0 | J12: 2 | K12: 127.4 | L12: 1201 | M12: 1051 | N12: 2544 | O12: 0 | P12: 0 | Q12: 20.9 | R12: 0 | S12: 14.2 | T12: 0 | U12: 0 | V12: 0 | W12: 0 | X12: 704 | Y12: 16.5 | Z12: 32 | AA12: 0 | AB12: 0 | AC12: 0 | AD12: 10 | AE12: 6 | AF12: 3 | AG12: 0 | AH12: 0 | AI12: 0 | AJ12: -8 | AK12: -16 | AL12: -8 | AM12: -8 | AN12: 0 | AO12: 2 | AP12: 16 | AQ12: -1 | AR12: -255 | AS12: -255 | AT12: 9717.7 | AU12: 145 | AV12: 47.9 | AW12: 95.7 | AX12: 47.9 | AY12: 94.3 | AZ12: 1120 | BA12: 144 | BB12: 0 | BC12: 0 | BD12: 0 | BE12: 0 | BF12: 1 | BG12: 0 | BH12: 0 | BI12: 0 | BJ12: 7389992 | BK12: 11998.05 | BL12: 7549922 | BM12: 810 | BN12: 0 | BO12: -0.236 | BP12: 22 | BQ12: 796 | BR12: 14.5 | BS12: 10587.9 | BT12: 104 | BU12: 0 | BV12: 0 | BW12: 1 | BX12: 33.8 | BY12: 99 | BZ12: 44.5 | CA12: 72.44 | CB12: 22.53 | CC12: 22.47 | CD12: 538.63 | CE12: 127 | CF12: 32 | CG12: 295.3 | CH12: 32 | CI12: 0 | CJ12: 50.89 | CK12: 0.41 | CL12: 0 | CM12: 0 | CN12: 0 | CO12: 0 | CP12: 0 | CQ12: 0 | CR12: Not Supported | CS12: Not Supported | CT12: 16515 | CU12: 1 | CV12: 865 | CW12: 1 | CX12: 1 | CY12: 821.44 | CZ12: 162 | DA12: 2016 | DB12: 0 | DC12: 14.4 | DD12: 204 | DE12: 4095 | DF12: 212 | DG12: 563 | DH12: 0 | DI12: 86 | DJ12: 0 | DK12: 1 | DL12: 0 | DM12: 1 | DN12: FALSE | DO12: 22.625 | DP12: 551
A13: -10 | B13: -1 | C13: 12.3 | D13: 1 | E13: 794 | F13: 109.4 | G13: 1688 | H13: -10 | I13: 0 | J13: 2 | K13: 127.4 | L13: 1201 | M13: 1051 | N13: 2544 | O13: 0 | P13: 0 | Q13: 20.9 | R13: 0 | S13: 14.2 | T13: 0 | U13: 0 | V13: 0 | W13: 0 | X13: 704 | Y13: 16.5 | Z13: 32 | AA13: 0 | AB13: 0 | AC13: 0 | AD13: 10 | AE13: 6 | AF13: 3 | AG13: 0 | AH13: 0 | AI13: 0 | AJ13: -8 | AK13: -16 | AL13: -8 | AM13: -8 | AN13: 0 | AO13: 2 | AP13: 16 | AQ13: -1 | AR13: -255 | AS13: -255 | AT13: 9717.7 | AU13: 145 | AV13: 47.9 | AW13: 95.7 | AX13: 47.9 | AY13: 94.3 | AZ13: 1120 | BA13: 144 | BB13: 0 | BC13: 0 | BD13: 0 | BE13: 0 | BF13: 1 | BG13: 0 | BH13: 0 | BI13: 0 | BJ13: 7389992 | BK13: 11998.05 | BL13: 7549922 | BM13: 810 | BN13: 0 | BO13: -0.236 | BP13: 22 | BQ13: 796 | BR13: 14.5 | BS13: 10587.9 | BT13: 104 | BU13: 0 | BV13: 0 | BW13: 1 | BX13: 33.8 | BY13: 99 | BZ13: 44.5 | CA13: 72.44 | CB13: 22.53 | CC13: 22.47 | CD13: 538.63 | CE13: 127 | CF13: 32 | CG13: 295.3 | CH13: 32 | CI13: 0 | CJ13: 50.89 | CK13: 0.41 | CL13: 0 | CM13: 0 | CN13: 0 | CO13: 0 | CP13: 0 | CQ13: 0 | CR13: Not Supported | CS13: Not Supported | CT13: 16515 | CU13: 1 | CV13: 865 | CW13: 1 | CX13: 1 | CY13: 821.44 | CZ13: 162 | DA13: 2016 | DB13: 0 | DC13: 14.4 | DD13: 200 | DE13: 4095 | DF13: 224 | DG13: 578 | DH13: 0 | DI13: 86 | DJ13: 0 | DK13: 2 | DL13: 0 | DM13: 1 | DN13: FALSE | DO13: 22.625 | DP13: 551
A14: -9 | B14: -0.9 | C14: 12.3 | D14: 1 | E14: 794 | F14: 109.4 | G14: 1688 | H14: -10 | I14: 0 | J14: 2 | K14: 127.4 | L14: 1201 | M14: 1051 | N14: 2544 | O14: 0 | P14: 0 | Q14: 20.9 | R14: 0 | S14: 14.2 | T14: 0 | U14: 0 | V14: 0 | W14: 0 | X14: 704 | Y14: 16.5 | Z14: 32 | AA14: 0 | AB14: 0 | AC14: 0 | AD14: 10 | AE14: 6 | AF14: 3 | AG14: 0 | AH14: 0 | AI14: 0 | AJ14: -8 | AK14: -16 | AL14: -8 | AM14: -8 | AN14: 0 | AO14: 2 | AP14: 16 | AQ14: -1 | AR14: -255 | AS14: -255 | AT14: 9717.7 | AU14: 145 | AV14: 47.9 | AW14: 95.7 | AX14: 47.9 | AY14: 94.3 | AZ14: 1120 | BA14: 144 | BB14: 0 | BC14: 0 | BD14: 0 | BE14: 0 | BF14: 1 | BG14: 0 | BH14: 0 | BI14: 0 | BJ14: 7389992 | BK14: 11998.05 | BL14: 7549922 | BM14: 810 | BN14: 0 | BO14: -0.236 | BP14: 22 | BQ14: 796 | BR14: 14.5 | BS14: 10587.9 | BT14: 104 | BU14: 0 | BV14: 0 | BW14: 1 | BX14: 33.8 | BY14: 99 | BZ14: 44.5 | CA14: 72.44 | CB14: 22.53 | CC14: 22.47 | CD14: 538.63 | CE14: 127 | CF14: 32 | CG14: 295.3 | CH14: 32 | CI14: 0 | CJ14: 50.89 | CK14: 0.41 | CL14: 0 | CM14: 0 | CN14: 0 | CO14: 0 | CP14: 0 | CQ14: 0 | CR14: Not Supported | CS14: Not Supported | CT14: 16515 | CU14: 1 | CV14: 865 | CW14: 1 | CX14: 1 | CY14: 821.44 | CZ14: 162 | DA14: 2016 | DB14: 0 | DC14: 14.4 | DD14: 200 | DE14: 4095 | DF14: 224 | DG14: 578 | DH14: 0 | DI14: 86 | DJ14: 0 | DK14: 2 | DL14: 0 | DM14: 1 | DN14: FALSE | DO14: 22.188 | DP14: 546
A15: -8 | B15: -0.8 | C15: 12.5 | D15: 1 | E15: 794 | F15: 109.4 | G15: 1688 | H15: -10 | I15: 0 | J15: 2 | K15: 127.4 | L15: 1201 | M15: 1051 | N15: 2544 | O15: 0 | P15: 0 | Q15: 20.9 | R15: 0 | S15: 14.2 | T15: 0 | U15: 0 | V15: 0 | W15: 0 | X15: 704 | Y15: 16.5 | Z15: 32 | AA15: 0 | AB15: 0 | AC15: 0 | AD15: 10 | AE15: 6 | AF15: 3 | AG15: 0 | AH15: 0 | AI15: 0 | AJ15: -8 | AK15: -16 | AL15: -8 | AM15: -8 | AN15: 0 | AO15: 2 | AP15: 16 | AQ15: -1 | AR15: -255 | AS15: -255 | AT15: 9717.7 | AU15: 145 | AV15: 47.9 | AW15: 95.7 | AX15: 47.9 | AY15: 94.3 | AZ15: 1120 | BA15: 144 | BB15: 0 | BC15: 0 | BD15: 0 | BE15: 0 | BF15: 1 | BG15: 0 | BH15: 0 | BI15: 0 | BJ15: 7389992 | BK15: 11998.05 | BL15: 7549922 | BM15: 810 | BN15: 0 | BO15: -0.236 | BP15: 22 | BQ15: 796 | BR15: 14.5 | BS15: 10587.9 | BT15: 104 | BU15: 0 | BV15: 0 | BW15: 1 | BX15: 33.8 | BY15: 99 | BZ15: 44.5 | CA15: 72.44 | CB15: 22.53 | CC15: 22.47 | CD15: 538.63 | CE15: 127 | CF15: 32 | CG15: 295.3 | CH15: 32 | CI15: 0 | CJ15: 50.89 | CK15: 0.41 | CL15: 0 | CM15: 0 | CN15: 0 | CO15: 0 | CP15: 0 | CQ15: 0 | CR15: Not Supported | CS15: Not Supported | CT15: 16515 | CU15: 1 | CV15: 865 | CW15: 1 | CX15: 1 | CY15: 821.44 | CZ15: 162 | DA15: 2016 | DB15: 0 | DC15: 14.4 | DD15: 200 | DE15: 4095 | DF15: 224 | DG15: 578 | DH15: 0 | DI15: 86 | DJ15: 0 | DK15: 2 | DL15: 0 | DM15: 1 | DN15: FALSE | DO15: 22.188 | DP15: 546
A16: -7 | B16: -0.7 | C16: 12.5 | D16: 1 | E16: 794 | F16: 109.4 | G16: 1688 | H16: -10 | I16: 0 | J16: 2 | K16: 127.4 | L16: 1153 | M16: 1051 | N16: 2544 | O16: 0 | P16: 0 | Q16: 20.9 | R16: 0 | S16: 14.2 | T16: 0 | U16: 0 | V16: 0 | W16: 0 | X16: 704 | Y16: 16.5 | Z16: 32 | AA16: 0 | AB16: 0 | AC16: 0 | AD16: 10 | AE16: 6 | AF16: 3 | AG16: 0 | AH16: 0 | AI16: 0 | AJ16: -8 | AK16: -16 | AL16: -8 | AM16: -8 | AN16: 0 | AO16: 2 | AP16: 16 | AQ16: -1 | AR16: -255 | AS16: -255 | AT16: 9717.7 | AU16: 145 | AV16: 47.9 | AW16: 95.7 | AX16: 47.9 | AY16: 94.3 | AZ16: 1120 | BA16: 144 | BB16: 0 | BC16: 0 | BD16: 0 | BE16: 0 | BF16: 1 | BG16: 0 | BH16: 0 | BI16: 0 | BJ16: 7389992 | BK16: 11998.05 | BL16: 7549922 | BM16: 810 | BN16: 0 | BO16: -0.236 | BP16: 22 | BQ16: 796 | BR16: 14.5 | BS16: 10587.9 | BT16: 104 | BU16: 0 | BV16: 0 | BW16: 1 | BX16: 33.8 | BY16: 99 | BZ16: 44.5 | CA16: 72.44 | CB16: 22.53 | CC16: 22.47 | CD16: 538.63 | CE16: 127 | CF16: 32 | CG16: 295.3 | CH16: 32 | CI16: 0 | CJ16: 50.89 | CK16: 0.41 | CL16: 0 | CM16: 0 | CN16: 0 | CO16: 0 | CP16: 0 | CQ16: 0 | CR16: Not Supported | CS16: Not Supported | CT16: 16515 | CU16: 1 | CV16: 865 | CW16: 1 | CX16: 1 | CY16: 821.44 | CZ16: 162 | DA16: 2016 | DB16: 0 | DC16: 14.4 | DD16: 200 | DE16: 4095 | DF16: 224 | DG16: 578 | DH16: 0 | DI16: 86 | DJ16: 0 | DK16: 2 | DL16: 0 | DM16: 1 | DN16: FALSE | DO16: 22.188 | DP16: 546
... A351: 328 | B351: 32.8 | C351: 13.2 | D351: 1 | E351: 794 | F351: 105.8 | G351: 1688 | H351: -10 | I351: 0 | J351: 0 | K351: 134.6 | L351: 0 | M351: 1051 | N351: 2544 | O351: 0 | P351: 0 | Q351: 62.7 | R351: 0 | S351: 14.2 | T351: 0 | U351: 0 | V351: 0 | W351: 0 | X351: 704 | Y351: 16.2 | Z351: 46.4 | AA351: 0 | AB351: 0 | AC351: 0 | AD351: 11 | AE351: 7 | AF351: 3 | AG351: 0 | AH351: 0 | AI351: 0 | AJ351: 0 | AK351: -8 | AL351: -4 | AM351: 0 | AN351: 0 | AO351: 1 | AP351: 11 | AQ351: -1 | AR351: -255 | AS351: -255 | AT351: 3481 | AU351: -319.1 | AV351: 50.8 | AW351: 65.3 | AX351: 50.8 | AY351: 0 | AZ351: 1120 | BA351: 280 | BB351: 0 | BC351: 0 | BD351: 0 | BE351: 0 | BF351: 1 | BG351: 0 | BH351: 0 | BI351: 0 | BJ351: 7390024 | BK351: 11998.06 | BL351: 7549956 | BM351: 100 | BN351: 0 | BO351: -0.236 | BP351: 0 | BQ351: 796 | BR351: 14.2 | BS351: 3771 | BT351: 96.8 | BU351: 0 | BV351: 0 | BW351: 0 | BX351: 84.2 | BY351: 99 | BZ351: 40.88 | CA351: 68.38 | CB351: 0.16 | CC351: 0 | CD351: 129.25 | CE351: 127 | CF351: 100.4 | CG351: 292.1 | CH351: 99.5 | CI351: 0 | CJ351: 53.9 | CK351: 0.19 | CL351: 0 | CM351: 0 | CN351: 0 | CO351: 0 | CP351: 0 | CQ351: 0 | CR351: Not Supported | CS351: Not Supported | CT351: 300000 | CU351: 0 | CV351: 4294967295 | CW351: 0 | CX351: 0 | CY351: 99.94 | CZ351: 263 | DA351: 2016 | DB351: 0 | DC351: 14.4 | DD351: 184 | DE351: 4095 | DF351: 216 | DG351: 0 | DH351: 0 | DI351: 84.2 | DJ351: 0 | DK351: 0 | DL351: 0 | DM351: 1 | DN351: FALSE | DO351: 0 | DP351: 194

Sheet Data 2
A1: Sel | B1: Num | C1: Service Data | D1: Variable | F1: Unit | L1: Paste New Data Here | M1: Paste Previous Data Here: | N1: Difference… Paste in E2 | O1: <- Use for evaluating last X number of hours (time between two snapshots)
B2: 3 | C2: Last EGR closed position (AD Conversion) | D2: P_L_Egr_close_pos_learnt_nvv | F2: ADcnt | G2: <- Copy from extracted dataset. Leave off 'Frame' and 'Time', then transpose paste | N2: =L2-M2 -> 0
B3: 4 | C3: First EGR closed position (AD Conversion) | D3: P_L_Egr_close_pos_mean_nvv | F3: ADcnt | N3: =L3-M3 -> 0
B4: 13 | C4: Engine cycle counter array for Injector 1 | D4: P_L_Inj_pls_cnt_cycle_inj_nvv[0] | F4: - | N4: =L4-M4 -> 0
B5: 14 | C5: Engine cycle counter array for Injector 3 (D18 = Injector 2) | D5: P_L_Inj_pls_cnt_cycle_inj_nvv[1] | F5: - | N5: =L5-M5 -> 0
B6: 15 | C6: Engine cycle counter array for Injector 4 (D18 = Injector 3) | D6: P_L_Inj_pls_cnt_cycle_inj_nvv[2] | F6: - | N6: =L6-M6 -> 0
B7: 16 | C7: Engine cycle counter array for Injector 2 | D7: P_L_Inj_pls_cnt_cycle_inj_nvv[3] | F7: - | N7: =L7-M7 -> 0
B8: 17 | C8: All injectors pulse counter array for engine cycles | D8: P_L_Inj_pls_cnt_cycle_nvv | F8: - | N8: =L8-M8 -> 0
B9: 18 | C9: Injector 1 pulse counter array for Main injection | D9: P_L_Inj_pls_cnt_main_nvv_0 | F9: - | N9: =L9-M9 -> 0
B10: 19 | C10: Injector 3 pulse counter array for Main injection (D18 = Injector 2) | D10: P_L_Inj_pls_cnt_main_nvv_1 | F10: - | N10: =L10-M10 -> 0
B11: 20 | C11: Injector 4 pulse counter array for Main injection (D18 = Injector 3) | D11: P_L_Inj_pls_cnt_main_nvv_2 | F11: - | N11: =L11-M11 -> 0
B12: 21 | C12: Injector 2 pulse counter array for Main injection | D12: P_L_Inj_pls_cnt_main_nvv_3 | F12: - | N12: =L12-M12 -> 0
B13: 22 | C13: Pulse counter array for Main and After pulses type Recovery value = 0 | D13: P_L_Inj_pls_cnt_main_nvv_4 | F13: - | N13: =L13-M13 -> 0
B14: 23 | C14: Pulse counter array for Main and After pulses type Recovery value = 0 | D14: P_L_Inj_pls_cnt_main_nvv_5 | F14: - | N14: =L14-M14 -> 0
... B81: 90 | C81: Trim value(IMV learn value) | D81: RPC_Im_crt_trim_lim_nvv | F81: mA | N81: =L81-M81 -> 0
B82: 91 | C82: Initial Trim value(IMV learn value) | D82: RPC_Im_init_hi_bkpt_updated_nvv | N82: =L82-M82 -> 0
B83: 92 | C83: Time spent in an overpressure condition | D83: RPC_Tl_overpressure_duration_nvv | F83: hour | N83: =L83-M83 -> 0
B84: 93 | C84: The priming of the system is done | D84: RPC_Tl_priming_done_nvv | N84: =L84-M84 -> 0
B85: 94 | C85: Rail pressure stored in NVM for calibration test | D85: STE_Railp_cal_nvv | F85: psi | N85: =L85-M85 -> 0
B86: 95 | C86: Number of regeneration started due to engine out soot mass | D86: P_T_Dpf_chk_rgn_start_engout_nvv | F86: - | N86: =L86-M86 -> 0
B87: 96 | C87: Number of regeneration started due to model soot mass | D87: P_T_Dpf_chk_rgn_start_model_nvv | F87: - | N87: =L87-M87 -> 0
B88: 97 | C88: Number of regeneration started due to the force regen switch | D88: P_T_Dpf_chk_rgn_start_switch_nvv | N88: =L88-M88 -> 0
B89: 98 | C89: Number of regeneration started due to time | D89: P_T_Dpf_chk_rgn_start_time_nvv | N89: =L89-M89 -> 0
B90: 99 | C90: Number of regeneration stopped due to model soot mass | D90: P_T_Dpf_chk_rgn_stop_model_nvv | F90: - | N90: =L90-M90 -> 0
B91: 100 | C91: Memorize the last "total regen time" when regeneration is not aborted | D91: P_T_Dpf_last_end_regen_time_nvv | F91: hour | N91: =L91-M91 -> 0
B92: 101 | C92: Engine run time when last regeneration finished without being aborted | D92: P_T_Dpf_last_end_regen_time2_nvv | F92: hour | N92: =L92-M92 -> 0
B93: 102 | C93: Engine run time when last regeneration finished | D93: P_T_Dpf_last_regen_time_nvv | F93: hour | N93: =L93-M93 -> 0
B94: 103 | C94: modeled sulfur mass in SCR | D94: P_T_Dpf_model_soot_mass_nvv | F94: g | N94: =L94-M94 -> 0
B95: 104 | C95: Array including the last regenerations time intervals | D95: P_T_Dpf_mon_rgn_hist_runtime_nvv[0] | F95: hour | N95: =L95-M95 -> 0
B96: 105 | C96: Array including the last regenerations time intervals | D96: P_T_Dpf_mon_rgn_hist_runtime_nvv[1] | F96: hour | N96: =L96-M96 -> 0
B97: 106 | C97: Array including the last regenerations time intervals | D97: P_T_Dpf_mon_rgn_hist_runtime_nvv[2] | F97: hour | N97: =L97-M97 -> 0
B98: 107 | C98: Array including the last regenerations time intervals | D98: P_T_Dpf_mon_rgn_hist_runtime_nvv[3] | F98: hour | N98: =L98-M98 -> 0
B99: 108 | C99: Array including the last regenerations time intervals | D99: P_T_Dpf_mon_rgn_hist_runtime_nvv[4] | F99: hour | N99: =L99-M99 -> 0
B100: 109 | C100: Array including the last regenerations durations | D100: P_T_Dpf_mon_rgn_hist_time_nvv[0] | F100: hour | N100: =L100-M100 -> 0
B101: 110 | C101: Array including the last regenerations durations | D101: P_T_Dpf_mon_rgn_hist_time_nvv[1] | F101: hour | N101: =L101-M101 -> 0
... B107: 116 | C107: Total time in regeneration due to normal start condition for vehicle life | D107: P_T_Dpf_regen_total_time_nvv | F107: hour | N107: =L107-M107 -> 0
B108: 117 | C108: DPF configuration (1: DPF / 0: Normal) | D108: APP_DPF_PRESENT_NVV | N108: =L108-M108 -> 0
B109: 118 | C109: This flag indicates that the unit was never running before | D109: IN_Bal_first_init_done_nvv | N109: =L109-M109 -> 0
B110: 119 | C110: NVM value for the correction which must be apply to the measurement for speed calculation | D110: IN_Bal_tooth_error_nvv | F110: ADcnt | N110: =L110-M110 -> 0
B111: 120 | C111: Resistance level stored for each injector to correct the battery voltage variations | D111: P_L_Inj_brc_init_resistance_nvv[0] | F111: Ohm | N111: =L111-M111 -> 0
...

Sheet Starting

Sheet Turbo
U12: =(MAX('Data 1'!BR5:BR2000))-U14 -> 0.9 | V12: Max Boost
U13: =MIN('Data 1'!BR15:BR2000) -> 14.2 | V13: Minimum Absolute Manifold Pressure
U14: =AVERAGE('Data 1'!S5:S2000) -> 14.2 | V14: Atmosphere
U15: =U14-U13 -> -9.2370556e-14 | V15: Turbo drag
V19: `

Sheet Fuel

Sheet Injector
L3: Read during steady state runnung
L4: If a piston is slow, it can be assumed that the cylinder does not combust well.
L5: If the instantaneous speed of a particular cylinder is too high, the injector may be leaking fuel
B28: MDP Learning (Test injector outside +100 /-100 Micro Second Range) | O28: MDP Updates (Compare relative number of updates. Test injectors with low numbers.)
R31: Injector 1 | S31: ='Data 2'!E71 -> 0 | Y31: Number of MDP update failed | Z31: ='Data 2'!E75 -> 0
R32: (D18 = Injector 2) Injector 3 | S32: ='Data 2'!E72 -> 0 | Y32: Number of MDP update succeed | Z32: ='Data 2'!E76 -> 0
R33: (D18 = Injector 3) Injector 4 | S33: ='Data 2'!E73 -> 0 | Z33: =Z32/(Z31+Z32) -> #DIV/0!
R34: Injector 2 | S34: ='Data 2'!E74 -> 0 | X34: (The typical success rate is ~75%.)
X35: (Troubleshoot injectors at <50%)
T38: `

Sheet EUD
A2: Engine Usage Data ( EUD ) | S2: Bubble data
M3: Total run time (Sec) | N3: Total run time (Hrs) | S3: =$C$60 -> 900 | T3: 0.05 | U3: =C61 -> #DIV/0!
M4: =SUM(D46:M55) -> 0 | N4: =M4/3600 -> 0 | O4: (Table Validation) | S4: =$C$60 -> 900 | T4: 0.15 | U4: =C62 -> #DIV/0!
M5: Engine run time (Data 2 PID) | N5: ='Data 2'!E134/3600 -> 0 | S5: =$C$60 -> 900 | T5: 0.25 | U5: =C63 -> #DIV/0!
M6: Engine run time (Data 1 PID) | N6: ='Data 1'!BJ5/3600 -> 2052.7753 | S6: =$C$60 -> 900 | T6: 0.35 | U6: =C64 -> #DIV/0!
M7: Ignition on time (Data 1 PID) | N7: ='Data 1'!BL5/3600 -> 2097.2003 | S7: =$C$60 -> 900 | T7: 0.45 | U7: =C65 -> #DIV/0!
M8: Idle | N8: ='Data 2'!E125/3600 -> 0 | S8: =$C$60 -> 900 | T8: 0.55 | U8: =C66 -> #DIV/0!
S9: =$C$60 -> 900 | T9: 0.65 | U9: =C67 -> #DIV/0!
S10: =$C$60 -> 900 | T10: 0.75 | U10: =C68 -> #DIV/0!
S11: =$C$60 -> 900 | T11: 0.85 | U11: =C69 -> #DIV/0!
S12: =$C$60 -> 900 | T12: 0.9 | U12: =C70 -> #DIV/0!
S13: =$D$60 -> 1100 | T13: =T3 -> 0.05 | U13: =D61 -> #DIV/0!
S14: =$D$60 -> 1100 | T14: =T4 -> 0.15 | U14: =D62 -> #DIV/0!
S15: =$D$60 -> 1100 | T15: =T5 -> 0.25 | U15: =D63 -> #DIV/0!
S16: =$D$60 -> 1100 | T16: =T6 -> 0.35 | U16: =D64 -> #DIV/0!
S17: =$D$60 -> 1100 | T17: =T7 -> 0.45 | U17: =D65 -> #DIV/0!
S18: =$D$60 -> 1100 | T18: =T8 -> 0.55 | U18: =D66 -> #DIV/0!
S19: =$D$60 -> 1100 | T19: =T9 -> 0.65 | U19: =D67 -> #DIV/0!
S20: =$D$60 -> 1100 | T20: =T10 -> 0.75 | U20: =D68 -> #DIV/0!
S21: =$D$60 -> 1100 | T21: =T11 -> 0.85 | U21: =D69 -> #DIV/0!
S22: =$D$60 -> 1100 | T22: =T12 -> 0.9 | U22: =D70 -> #DIV/0!
S23: =$E$60 -> 1300 | T23: =T13 -> 0.05 | U23: =E61 -> #DIV/0!
S24: =$E$60 -> 1300 | T24: =T14 -> 0.15 | U24: =E62 -> #DIV/0!
S25: =$E$60 -> 1300 | T25: =T15 -> 0.25 | U25: =E63 -> #DIV/0!
S26: =$E$60 -> 1300 | T26: =T16 -> 0.35 | U26: =E64 -> #DIV/0!
S27: =$E$60 -> 1300 | T27: =T17 -> 0.45 | U27: =E65 -> #DIV/0!
S28: =$E$60 -> 1300 | T28: =T18 -> 0.55 | U28: =E66 -> #DIV/0!
S29: =$E$60 -> 1300 | T29: =T19 -> 0.65 | U29: =E67 -> #DIV/0!
S30: =$E$60 -> 1300 | T30: =T20 -> 0.75 | U30: =E68 -> #DIV/0!
S31: =$E$60 -> 1300 | T31: =T21 -> 0.85 | U31: =E69 -> #DIV/0!
S32: =$E$60 -> 1300 | T32: =T22 -> 0.9 | U32: =E70 -> #DIV/0!
S33: =$F$60 -> 1500 | T33: =T23 -> 0.05 | U33: =F61 -> #DIV/0!
S34: =$F$60 -> 1500 | T34: =T24 -> 0.15 | U34: =F62 -> #DIV/0!
S35: =$F$60 -> 1500 | T35: =T25 -> 0.25 | U35: =F63 -> #DIV/0!
S36: =$F$60 -> 1500 | T36: =T26 -> 0.35 | U36: =F64 -> #DIV/0!
S37: =$F$60 -> 1500 | T37: =T27 -> 0.45 | U37: =F65 -> #DIV/0!
S38: =$F$60 -> 1500 | T38: =T28 -> 0.55 | U38: =F66 -> #DIV/0!
S39: =$F$60 -> 1500 | T39: =T29 -> 0.65 | U39: =F67 -> #DIV/0!
S40: =$F$60 -> 1500 | T40: =T30 -> 0.75 | U40: =F68 -> #DIV/0!
S41: =$F$60 -> 1500 | T41: =T31 -> 0.85 | U41: =F69 -> #DIV/0!
...

Sheet EGR
A36: ='Data 2'!L2 -> 0 | B36: P_L_Egr_close_pos_learnt_nvv | E36: ='Data 2'!E2 -> 0 | F36: '- The normal learning range of the EGR Close position is learned from 3.6 to 4.3 V (690 to 910 cnts), but generally from 3.8 to 4 V (780 to 820 cnts).
A37: ='Data 2'!L3 -> 0 | B37: P_L_Egr_close_pos_mean_nvv | E37: ='Data 2'!E3 -> 0 | F37: '- If the EGR closed learning value is below almost 780cnts, you should suspect that EGR is not completely closed by carbon or foreign matter.

Sheet Temperatures
C35: =MIN('Data 1'!F5:F2000) -> 105.8 | D35: Min Fuel Temp
C36: =MIN('Data 1'!G5:G2000) -> 1688 | D36: Min Turbin In Temp

Sheet Engine oil pressure and speeds

Sheet WIF
